<?xml version="1.0" encoding="utf-8"?>
<!-- This URDF was automatically created by SolidWorks to URDF Exporter! Originally created by Stephen Brawner (brawner@gmail.com) 
     Commit Version: 1.6.0-4-g7f85cfe  Build Version: 1.6.7995.38578
     For more information, please see http://wiki.ros.org/sw_urdf_exporter -->
<robot
  name="leg_robot_4">
  <link
    name="base_link">
    <inertial>
      <origin
        xyz="0.0333301384983334 0.67103260442612409 0.697885837083768"
        rpy="0 0 0" />
      <mass
        value="1.49690133184426" />
      <inertia
        ixx="0.00329189748170828"
        ixy="-6.78095222817375E-08"
        ixz="-4.85227555996369E-07"
        iyy="0.00294239027368508"
        iyz="-5.65136146714161E-07"
        izz="0.00317388886396801" />
    </inertial>
    <visual>
      <origin
        xyz="0 0 0"
        rpy="0 0 0" />
      <geometry>
        <mesh
          filename="../meshes/base_link.STL" />
      </geometry>
      <material
        name="">
        <color
          rgba="1 1 1 1" />
      </material>
    </visual>
    <collision>
      <origin
        xyz="0 0 0"
        rpy="0 0 0" />
      <geometry>
        <mesh
          filename="../meshes/base_link.STL" />
      </geometry>
    </collision>
  </link>
  <link
    name="left_Link1">
    <inertial>
      <origin
        xyz="0.088851659780158 -0.000331637085429826 0.02750913532889"
        rpy="0 0 0" />
      <mass
        value="3.469473166492788" />
      <inertia
        ixx="0.000307595565290695"
        ixy="2.19819619350591E-06"
        ixz="-0.000182129639324375"
        iyy="0.000580819177282074"
        iyz="1.53210567122124E-06"
        izz="0.00045369969875024" />
    </inertial>
    <visual>
      <origin
        xyz="0 0 0"
        rpy="0 0 0" />
      <geometry>
        <mesh
          filename="../meshes/left_Link1.STL" />
      </geometry>
      <material
        name="">
        <color
          rgba="1 1 1 1" />
      </material>
    </visual>
    <collision>
      <origin
        xyz="0 0 0"
        rpy="0 0 0" />
      <geometry>
        <mesh
          filename="../meshes/left_Link1.STL" />
      </geometry>
    </collision>
  </link>
  <joint
    name="left_joint1"
    type="revolute">
    <origin
      xyz="0.074405 -0.0080455 0.67982"
      rpy="1.5708 0 0" />
    <parent
      link="base_link" />
    <child
      link="left_Link1" />
    <axis
      xyz="-1 0 0" />
    <limit
      lower="-0.75"
      upper="1.57"
      effort="63"
      velocity="20" />
  </joint>
  <link
    name="left_Link2">
    <inertial>
      <origin
        xyz="9.35953192587879E-07 -0.0762574506509951 0.017596614239338"
        rpy="0 0 0" />
      <mass
        value="1.08645850508858" />
      <inertia
        ixx="0.0014785711596645"
        ixy="-8.509908467779E-07"
        ixz="-1.28981575241324E-06"
        iyy="0.00218236702718317"
        iyz="-2.62516236789212E-05"
        izz="0.00178961925253272" />
    </inertial>
    <visual>
      <origin
        xyz="0 0 0"
        rpy="0 0 0" />
      <geometry>
        <mesh
          filename="../meshes/left_Link2.STL" />
      </geometry>
      <material
        name="">
        <color
          rgba="1 1 1 1" />
      </material>
    </visual>
    <collision>
      <origin
        xyz="0 0 0"
        rpy="0 0 0" />
      <geometry>
        <mesh
          filename="../meshes/left_Link2.STL" />
      </geometry>
    </collision>
  </link>
  <joint
    name="left_joint2"
    type="revolute">
    <origin
      xyz="0.14063 0.00016068 -0.013324"
      rpy="0 0 0" />
    <parent
      link="left_Link1" />
    <child
      link="left_Link2" />
    <axis
      xyz="0 -0.012059 0.99993" />
    <limit
      lower="-0.08"
      upper="1.45"
      effort="63"
      velocity="20" />
  </joint>
  <link
    name="left_Link3">
    <inertial>
      <origin
        xyz="0.00822876234553166 -0.304827746962222 -0.00369322736975432"
        rpy="0 0 0" />
      <mass
        value="1.60208478305264" />
      <inertia
        ixx="0.0138948980281397"
        ixy="-8.29118868668374E-06"
        ixz="-1.76694508858768E-07"
        iyy="0.00115580752075013"
        iyz="-0.00017967710035112"
        izz="0.012907492658796" />
    </inertial>
    <visual>
      <origin
        xyz="0 0 0"
        rpy="0 0 0" />
      <geometry>
        <mesh
          filename="../meshes/left_Link3.STL" />
      </geometry>
      <material
        name="">
        <color
          rgba="1 1 1 1" />
      </material>
    </visual>
    <collision>
      <origin
        xyz="0 0 0"
        rpy="0 0 0" />
      <geometry>
        <mesh
          filename="../meshes/left_Link3.STL" />
      </geometry>
    </collision>
  </link>
  <joint
    name="left_joint3"
    type="revolute">
    <origin
      xyz="0 -0.076656 0.012502"
      rpy="0 0 0" />
    <parent
      link="left_Link2" />
    <child
      link="left_Link3" />
    <axis
      xyz="0 0.99993 0.012059" />
    <limit
      lower="-1.05"
      upper="1.57"
      effort="35"
      velocity="20" />
  </joint>
  <link
    name="left_Link4">
    <inertial>
      <origin
        xyz="-0.0529070029782021 -0.104634142840928 -0.00757778919629163"
        rpy="0 0 0" />
      <mass
        value="1.06517552807913" />
      <inertia
        ixx="0.00475103587154659"
        ixy="1.03052666819589E-06"
        ixz="5.00921503145521E-08"
        iyy="0.000363762862712759"
        iyz="-5.70889404450472E-05"
        izz="0.00457610954754629" />
    </inertial>
    <visual>
      <origin
        xyz="0 0 0"
        rpy="0 0 0" />
      <geometry>
        <mesh
          filename="../meshes/left_Link4.STL" />
      </geometry>
      <material
        name="">
        <color
          rgba="1 1 1 1" />
      </material>
    </visual>
    <collision>
      <origin
        xyz="0 0 0"
        rpy="0 0 0" />
      <geometry>
        <mesh
          filename="../meshes/left_Link4.STL" />
      </geometry>
    </collision>
  </link>
  <joint
    name="left_joint4"
    type="revolute">
    <origin
      xyz="0.049 -0.48196 -0.0058122"
      rpy="0 0 0" />
    <parent
      link="left_Link3" />
    <child
      link="left_Link4" />
    <axis
      xyz="-1 0 0" />
    <limit
      lower="-2"
      upper="0"
      effort="30.6"
      velocity="15" />
  </joint>
  <link
    name="left_Link5">
    <inertial>
      <origin
        xyz="0.000251667253197002 -0.0292044657081603 -0.0376606206082752"
        rpy="0 0 0" />
      <mass
        value="0.276071717463909" />
      <inertia
        ixx="0.000285928353690902"
        ixy="1.94330197753284E-06"
        ixz="2.34221157246751E-08"
        iyy="5.70229975490586E-05"
        iyz="-2.3956388107617E-06"
        izz="0.000255646675993595" />
    </inertial>
    <visual>
      <origin
        xyz="0 0 0"
        rpy="0 0 0" />
      <geometry>
        <mesh
          filename="../meshes/left_Link5.STL" />
      </geometry>
      <material
        name="">
        <color
          rgba="0.898039215686275 0.917647058823529 0.929411764705882 1" />
      </material>
    </visual>
    <collision>
      <origin
        xyz="0 0 0"
        rpy="0 0 0" />
      <geometry>
        <mesh
          filename="../meshes/left_Link5.STL" />
      </geometry>
    </collision>
  </link>
  <joint
    name="left_joint5"
    type="revolute">
    <origin
      xyz="-0.049 -0.25742 0.032898"
      rpy="0 0 0" />
    <parent
      link="left_Link4" />
    <child
      link="left_Link5" />
    <axis
      xyz="0 -0.012059 0.99993" />
    <limit
      lower="-0.5"
      upper="0.5"
      effort="4"
      velocity="10" />
  </joint>
  <link
    name="left_Link6">
    <inertial>
      <origin
        xyz="-0.0437056095034989 -0.0126444231109442 0.0109673593360841"
        rpy="0 0 0" />
      <mass
        value="1.25173482349334" />
      <inertia
        ixx="0.00221587722669508"
        ixy="-4.09271287243686E-05"
        ixz="3.27923575098428E-05"
        iyy="0.00192790168163853"
        iyz="0.000322150902158661"
        izz="0.000761945243365007" />
    </inertial>
    <visual>
      <origin
        xyz="0 0 0"
        rpy="0 0 0" />
      <geometry>
        <mesh
          filename="../meshes/left_Link6.STL" />
      </geometry>
      <material
        name="">
        <color
          rgba="0.898039215686275 0.917647058823529 0.929411764705882 1" />
      </material>
    </visual>
    <collision>
      <origin
        xyz="0 0 0"
        rpy="0 0 0" />
      <geometry>
        <mesh
          filename="../meshes/left_Link6.STL" />
      </geometry>
    </collision>
  </link>
  <joint
    name="left_joint6"
    type="revolute">
    <origin
      xyz="0.052392 -0.069119 -0.036836"
      rpy="0 0 0" />
    <parent
      link="left_Link5" />
    <child
      link="left_Link6" />
    <axis
      xyz="0.99996 0.0084839 0.0001783" />
    <limit
      lower="-0.6"
      upper="1.3"
      effort="4"
      velocity="10" />
  </joint>
  <link
    name="right_Link1">
    <inertial>
      <origin
        xyz="-0.0888516568342693 5.69432960473293E-06 0.027511155133394"
        rpy="0 0 0" />
      <mass
        value="3.469474958062602" />
      <inertia
        ixx="0.000307596278049938"
        ixy="3.84275155890697E-08"
        ixz="0.000182142100703291"
        iyy="0.000580835822721732"
        iyz="-2.59088708029145E-08"
        izz="0.000453681028456837" />
    </inertial>
    <visual>
      <origin
        xyz="0 0 0"
        rpy="0 0 0" />
      <geometry>
        <mesh
          filename="../meshes/right_Link1.STL" />
      </geometry>
      <material
        name="">
        <color
          rgba="1 1 1 1" />
      </material>
    </visual>
    <collision>
      <origin
        xyz="0 0 0"
        rpy="0 0 0" />
      <geometry>
        <mesh
          filename="../meshes/right_Link1.STL" />
      </geometry>
    </collision>
  </link>
  <joint
    name="right_joint1"
    type="revolute">
    <origin
      xyz="-0.0077449 -0.0080455 0.67982"
      rpy="1.5708 0 0" />
    <parent
      link="base_link" />
    <child
      link="right_Link1" />
    <axis
      xyz="1 0 0" />
    <limit
      lower="-1.57"
      upper="0.75"
      effort="63"
      velocity="20" />
  </joint>
  <link
    name="right_Link2">
    <inertial>
      <origin
        xyz="-4.38095032667674E-07 -0.076036764225861 0.018530029662752"
        rpy="0 0 0" />
      <mass
        value="1.0864584420749" />
      <inertia
        ixx="0.00147851074616316"
        ixy="-1.10347304742056E-06"
        ixz="-1.10182705446302E-06"
        iyy="0.00218183328697101"
        iyz="-3.10669873097236E-05"
        izz="0.00179021288933082" />
    </inertial>
    <visual>
      <origin
        xyz="0 0 0"
        rpy="0 0 0" />
      <geometry>
        <mesh
          filename="../meshes/right_Link2.STL" />
      </geometry>
      <material
        name="">
        <color
          rgba="1 1 1 1" />
      </material>
    </visual>
    <collision>
      <origin
        xyz="0 0 0"
        rpy="0 0 0" />
      <geometry>
        <mesh
          filename="../meshes/right_Link2.STL" />
      </geometry>
    </collision>
  </link>
  <joint
    name="right_joint2"
    type="revolute">
    <origin
      xyz="-0.14063 0 -0.013325"
      rpy="0 0 0" />
    <parent
      link="right_Link1" />
    <child
      link="right_Link2" />
    <axis
      xyz="0 0.00020514 1" />
    <limit
      lower="-1.45"
      upper="0.08"
      effort="6"
      velocity="20" />
  </joint>
  <link
    name="right_Link3">
    <inertial>
      <origin
        xyz="-0.00822876234704453 -0.305002360917959 2.95066752287413E-05"
        rpy="0 0 0" />
      <mass
        value="1.60208478387031" />
      <inertia
        ixx="0.0138950635853602"
        ixy="8.23856486133477E-06"
        ixz="-5.78962498053342E-08"
        iyy="0.00115237426677091"
        iyz="-3.68208476762078E-05"
        izz="0.0129110914701674" />
    </inertial>
    <visual>
      <origin
        xyz="0 0 0"
        rpy="0 0 0" />
      <geometry>
        <mesh
          filename="../meshes/right_Link3.STL" />
      </geometry>
      <material
        name="">
        <color
          rgba="1 1 1 1" />
      </material>
    </visual>
    <collision>
      <origin
        xyz="0 0 0"
        rpy="0 0 0" />
      <geometry>
        <mesh
          filename="../meshes/right_Link3.STL" />
      </geometry>
    </collision>
  </link>
  <joint
    name="right_joint3"
    type="revolute">
    <origin
      xyz="0 -0.076497 0.013441"
      rpy="0 0 0" />
    <parent
      link="right_Link2" />
    <child
      link="right_Link3" />
    <axis
      xyz="0 1 -0.00020514" />
    <limit
      lower="-1.57"
      upper="1.05"
      effort="35"
      velocity="20" />
  </joint>
  <link
    name="right_Link4">
    <inertial>
      <origin
        xyz="0.0528851622667241 -0.104719205003742 -0.00629402011289562"
        rpy="0 0 0" />
      <mass
        value="1.06517552794204" />
      <inertia
        ixx="0.00475103587022021"
        ixy="1.03106390206003E-06"
        ixz="3.74504200184114E-08"
        iyy="0.000362996234660156"
        iyz="-5.41671760057621E-06"
        izz="0.00457687617432029" />
    </inertial>
    <visual>
      <origin
        xyz="0 0 0"
        rpy="0 0 0" />
      <geometry>
        <mesh
          filename="../meshes/right_Link4.STL" />
      </geometry>
      <material
        name="">
        <color
          rgba="1 1 1 1" />
      </material>
    </visual>
    <collision>
      <origin
        xyz="0 0 0"
        rpy="0 0 0" />
      <geometry>
        <mesh
          filename="../meshes/right_Link4.STL" />
      </geometry>
    </collision>
  </link>
  <joint
    name="right_joint4"
    type="revolute">
    <origin
      xyz="-0.049 -0.482 9.888E-05"
      rpy="0 0 0" />
    <parent
      link="right_Link3" />
    <child
      link="right_Link4" />
    <axis
      xyz="1 0 0" />
    <limit
      lower="0"
      upper="2"
      effort="30.6"
      velocity="15" />
  </joint>
  <link
    name="right_Link5">
    <inertial>
      <origin
        xyz="0.000158359784373396 -0.0296647721168645 -0.0372996338185962"
        rpy="0 0 0" />
      <mass
        value="0.276071716143871" />
      <inertia
        ixx="0.000285938316707634"
        ixy="1.2229242286118E-06"
        ixz="-2.64052738394452E-10"
        iyy="5.69841539329949E-05"
        iyz="4.07608100088745E-08"
        izz="0.000255675558134185" />
    </inertial>
    <visual>
      <origin
        xyz="0 0 0"
        rpy="0 0 0" />
      <geometry>
        <mesh
          filename="../meshes/right_Link5.STL" />
      </geometry>
      <material
        name="">
        <color
          rgba="0.898039215686275 0.917647058823529 0.929411764705882 1" />
      </material>
    </visual>
    <collision>
      <origin
        xyz="0 0 0"
        rpy="0 0 0" />
      <geometry>
        <mesh
          filename="../meshes/right_Link5.STL" />
      </geometry>
    </collision>
  </link>
  <joint
    name="right_joint5"
    type="revolute">
    <origin
      xyz="0.049 -0.25699 0.036053"
      rpy="0 0 0" />
    <parent
      link="right_Link4" />
    <child
      link="right_Link5" />
    <axis
      xyz="0 0.00020514 1" />
    <limit
      lower="-0.5"
      upper="0.5"
      effort="4"
      velocity="10" />
  </joint>
  <link
    name="right_Link6">
    <inertial>
      <origin
        xyz="0.0440681338776377 -0.0107292571323514 0.0123642466189018"
        rpy="0 0 0" />
      <mass
        value="1.25173227418432" />
      <inertia
        ixx="0.00221473522382905"
        ixy="4.03000665038196E-05"
        ixz="-4.05923979496004E-05"
        iyy="0.00198616329978931"
        iyz="0.000183314263585005"
        izz="0.000704804863625323" />
    </inertial>
    <visual>
      <origin
        xyz="0 0 0"
        rpy="0 0 0" />
      <geometry>
        <mesh
          filename="../meshes/right_Link6.STL" />
      </geometry>
      <material
        name="">
        <color
          rgba="0.898039215686275 0.917647058823529 0.929411764705882 1" />
      </material>
    </visual>
    <collision>
      <origin
        xyz="0 0 0"
        rpy="0 0 0" />
      <geometry>
        <mesh
          filename="../meshes/right_Link6.STL" />
      </geometry>
    </collision>
  </link>
  <joint
    name="right_joint6"
    type="revolute">
    <origin
      xyz="-0.051625 -0.070284 -0.035986"
      rpy="0 0 0" />
    <parent
      link="right_Link5" />
    <child
      link="right_Link6" />
    <axis
      xyz="-0.99999 -0.0053396 0" />
    <limit
      lower="-1.3"
      upper="0.6"
      effort="4"
      velocity="10" />
  </joint>
</robot>